Workbook

Sheet はじめに
A1: RINCLE 収益モデル — この資料の読み方ガイド
A3: この資料は「RINCLE（スポーツバイクレンタル事業）は、もうかる仕組みになっているか？ どうすればもうかるようになるか？」に答えるためのExcelです。本番データベースと決済サービス（Pay.jp）の実物のデータだけを使って作られており、推測や印象ではなく事実で議論するための土台になります。マーケティングや会計の知識がなくても読めるように作ってあります（分からない言葉は一番下の用語辞典へ）。
A4: このExcelが収益分析の「正本」（いちばん正しい元の資料）です。作成日: 2026-06-11 / 最終更新: 2026-06-12（6/12定例の判明事項を反映） / 数字の根拠はすべて「出典と経緯」シートに記録されています。
A6: ■ 全体の構成 — 12シートは4つのグループでできている
A7: 資料全体は「①現状を知る → ②計算する → ③目標を立てて追いかける」という流れで並んでいて、それを「④裏付け」グループが支えています。初めて読む人は上から順に。毎月の運用では「KPI進捗」だけ触れば回ります。
A8: ① 現状を知る | B8: 実態サマリー / 収益の論点 / 需給分析 | C8: いま何が起きているか・何が問題か
A9: ② 計算する | B9: コスト棚卸し / 試算モデル | C9: いくらかかって、何件でトントンか
A10: ③ 目標を立てて追う | B10: KPIツリー / KPI計画 / KPI進捗 | C10: どこを直すと伸びるか・目標と実績の管理
A11: ④ 裏付け | B11: 月別実績 / 確認リスト / 出典と経緯 | C11: 生の記録・聞くべきこと・数字の出どころ
A13: ■ マスの色のルール（全シート共通）
A14: 黄色のマス | B14: 自由に書き換えてOK。「前提」や「記入欄」。ここを変えると関係する計算が全部自動で変わる
A15: 青色のマス | B15: 自動計算。数式が入っているので触らない（壊しても直せるので焦らなくて大丈夫）
A16: ピンクのマス | B16: 「まだ確認できていない・仮置き・要注意」の印。本当のことが分かったら更新する
A18: ■ 各シートの説明（目的・何を管理・いつ使う・見方）
A19: シート | B19: 目的（なぜあるか） | C19: 何を管理しているか | D19: いつ使う・いつ更新する | E19: 見方のポイント
A20: 実態サマリー | B20: 「RINCLEは今どうなってる？」に1枚で答える。会議の出発点 | C20: データで確定した事実: 手数料15%・店舗54・利用者91人・実予約70件・実入金¥8,690。それとシステムのデータ異常（バグ）4件 | D20: 会議の冒頭での現状共有。新しい関係者への説明。大きな事実が変わったら更新 | E20: 最重要は実入金。Pay.jp分は¥8,690で、店頭決済分は紙請求でシステム外回収（6/12判明）。紙でも15%で請求していたと思われ、突合は不要と判断（6/12）
A21: 収益の論点 | B21: 「なぜもうかっていないか」と「どう直すか」の選択肢を示す。意思決定のための材料 | C21: 問題4つ（論点①〜④）とそれぞれの打ち手。最大の論点①=店頭決済の手数料は紙請求で回収済みと判明（6/12）、課題は未回収から「見える化」へ | D21: クライアントとの定例で「回収をどうするか」を決めるとき | E21: 打ち手は3案併記してある。どれを選ぶかはクライアントの経営判断（こちらは選択肢と根拠を出す役）
A22: コスト棚卸し | B22: 毎月出ていくお金を確定させる。「何件でトントンか」の分母になる | C22: 固定費の内訳リスト（サーバー代・人件費など）。確定/仮置き/要確認の状態つき | D22: クライアントから固定費の回答が来たら黄色マスに実数を記入。新しい固定費（広告など）が発生したら行を足す | E22: 合計は2段: 運営固定費（約¥18,300・試算モデルに連動）と、開発委託費込みの全体支出（約¥102万）。委託費は投資扱いで損益分岐の分母には入れない
A23: 試算モデル | B23: 「もしも」を計算する電卓。会議中の質問にその場で答えるための道具 | C23: 前提5つ（手数料率/単価/件数/徴収率/固定費）と、月間損益・損益分岐の計算。下に件数×固定費の早見表 | D23: 会議で「予約が100件になったら？」「人件費を増やしたら？」と聞かれたとき、黄色マスを変えて見せる | E23: いくら数字をいじっても記録（月別実績）は壊れない。安心して遊んでいい
A24: 月別実績 | B24: 過去の事実の記録。トレンド（伸びてるか）を見る | C24: 月ごとの完了予約数と手数料収入の実額（2025-10〜） | D24: 月1回、月初にDBエクスポートを見て前月の行を追記。過去の行は書き換えない | E24: 2月以降「約2ヶ月で倍」のペースが本物かをここで確認し続ける
A25: KPIツリー | B25: 「どこを直せば収益が増えるか」の地図。施策の優先順位はここで決める | C25: 収益を掛け算に分解した構造（収益=セッション×CVR×単価×手数料率×回収率）と、各部品の現在値・担当施策 | D25: 新しい施策を思いついたとき（必ず「どの部品を動かす施策か」を1つ指定するルール）。KPIが赤になったとき原因を探しに来る | E25: ★印が2大ボトルネック: 入金の見える化（紙請求の突合・カード1本化）と流入700IP/月。逆にCVR4%と手数料15%は健全なので触らない
A26: KPI計画 | B26: 目標数字の設計図。クライアントと「いくらを目指すか」を握るための叩き台 | C26: 前提（成長率+20%/月など）と7〜12月の月次目標の試算。※目標設定は凍結中（2026-06-12方針）— ユーザー増・差別化実装・UX改善後に再開 | D26: クライアントとの目標交渉のとき。前提の黄色マスを変えると計画全体が自動で引き直される | E26: ピンクの注記2つは必読: ①目標が確定したら進捗シートに焼き付ける手順 ②確認#1の回答（6/12）を受けたKGI定義の変更メモ
A27: KPI進捗 | B27: 計画と現実のズレを毎月検知する。このExcelの運用の本体 | C27: KGI+KPI6つの月次の目標・実績・達成率。下にKGIの選定理由とKGI→KSF→KPIの対応表（なぜこの6個を測るのか） | D27: 月1回、実績だけ記入（15分）。前月比のトレンドを見る。達成率の色分けは目標設定の再開後から | E27: 赤が続くKPIが出たら「KPIツリー」シートに戻って原因の部品と施策を特定する、という往復で使う
A28: 需給分析 | B28: 「店は足りてるのにお客が来ていない」という戦略判断の根拠 | C28: 供給側（店舗54・自転車369台・全店カード決済可）と需要側（利用者91人・月700IP）のバランス、予約の関西偏在 | D28: 集客施策の地域優先順位を決めるとき。ヒアリング対象店舗の選定（実施済み） | E28: 象徴的な1行=「しまなみ海道の玄関口・尾道で22台が予約ゼロ」。需要づくりが全ての鍵
A29: 確認リスト | B29: データでは分からないことを、クライアントに聞いて埋める管理表 | C29: 質問7つと回答記入欄（黄色）。6/12定例で#1〜4・#6は回答済み。残りは#5（リピート率）と#7（店舗数の対外表記） | D29: クライアント定例の前に見る。回答が来たら黄色に記入し、関係するシート（コスト棚卸し・KPI計画など）へ反映 | E29: #1は回答済み（紙請求で回収済み）。これを受けたKGI定義の変更はKPI計画シートの注記参照
A30: 出典と経緯 | B30: 「この数字どこから？」に全部答える。資料の信頼性の担保 | C30: データソース一覧・検証の訂正履歴（途中の誤分析も隠さず記録）・主要数値15個の出典対応表・今後の調査余地 | D30: 数字の根拠を聞かれたとき。半年後に見返して「なぜこうしたんだっけ」を思い出すとき | E30: 訂正履歴は失敗も含めて残してある — 「一度疑って検証済み」という意味で、数字の信頼性はむしろ高い
A32: ■ 毎月の運用（月初に15分）
A33: 1. BubbleのDataタブから予約・ユーザーをCSVエクスポートし、source/ フォルダに保存（このフォルダはGitHubに上がらない設定済み）
A34: 2. Pay.jp管理画面の「入金一覧」をスクショして source/payjp/ へ
A35: 3. 「月別実績」に前月の行を追記（完了予約数・手数料収入）
A36: 4. 「KPI進捗」に前月の実績を記入 → 達成率の色を見る
A37: 5. 赤いKPIがあれば「KPIツリー」で原因の部品を特定 → 対応する施策を打つ（これが月次レビュー）
A39: ■ イベントが起きたらやること
A40: クライアントから回答が来た | B40: 「確認リスト」の黄色に記入 → 関係するシートへ反映（例: リピート率#5→出典と経緯の調査余地、店舗数表記#7→実態サマリー）
A41: KGI目標をクライアントと握れた | B41: 「KPI進捗」の目標列を値貼り付けで固定（KPI計画シートのピンク注記に手順あり）
A42: GA4を設置した | B42: 「KPI進捗」のKPI3をユニークIP→GA4ユーザー数に切替、KPI4（Organic）の計測を開始
A44: ■ 用語ミニ辞典
A45: KGI | B45: 最終目標の数字（Key Goal Indicator）。この資料では「月間の実入金」。※目標額の設定は凍結中 — KPI計画シートに試算（12月¥120,000）だけ残してある
A46: KPI | B46: KGIに向かう途中経過を測る数字（Key Performance Indicator）。この資料では6個（完了予約数・回収率・セッション・Organic流入・CVR・稼働店舗数）
A47: KSF | B47: 成功のカギになる要因を言葉で言ったもの（Key Success Factor）。「回収の仕組みを作る」「流入を作る」など4つ。KPIはKSFを数字にしたもの
...

Sheet 実態サマリー
A1: RINCLE の実態サマリー（データ検証済みの事実）
A2: 分析日: 2026-06-11（本番データ）。出典・検証経緯は「出典と経緯」シート参照
A4: ■ 前提となる事実
A5: 項目 | B5: 値 | C5: 出所・備考
A6: プラットフォーム手数料 | B6: 15%（2026-04末〜05に10%から切替） | C6: 5月の完了予約21件すべて合計金額×15%と一致を確認
A7: カード手数料 3.3% | B7: 店舗負担 | C7: 決済フローAs-Is。PAY.JP公表のスタンダード料率（2026年6月時点）。契約上の実料率はPAY.JP管理画面で要確認
A8: 店舗側の合計負担率 | B8: 18.3% | C8: OTA相場（10〜20%・決済込み）の上限相当。追加値上げの余地は実質なし
A9: 登録店舗数 | B9: 54店舗 | C9: DBで確定。「100」は営業ベースの見込みと判明（6/12・確認#6）
A10: 登録利用者数 | B10: 91人（カード登録済み88人） | C10: users.csv
A11: 実予約（累計） | B11: 70件（完了49・キャンセル16・来客待ち5） | C11: 残り51レコードは「仮情報」=未確定ドラフト
A12: RINCLEの実入金（全期間） | B12: ¥8,690（+次回入金予定¥6,940） | C12: Pay.jp本番スクショで確定（売上一覧は全10件のみ）。※6/12判明: これはクレカ分のみで、店頭決済分は紙請求で別途回収済み（15%で請求していたと思われる・突合は不要と判断）
A14: ■ 予約レコード121件の内訳
A15: ステータス | B15: 件数 | C15: 手数料
A16: 返却済み（完了） | B16: 49 | C16: 全件記録あり（記録漏れゼロ）
A17: キャンセル | B17: 16 | C17: なし（課金前キャンセルのため正常）
A18: 来客待ち（未来の予約） | B18: 5 | C18: なし（ライド開始時課金のため正常）
A19: 仮情報（未確定ドラフト） | B19: 51 | C19: なし（予約番号も未採番）
A21: ■ 注目すべき率
A22: 指標 | B22: 値 | C22: 含意
A23: キャンセル率 | B23: 16/70 = 23% | C23: 高い。理由は天候+日程変更が大半（6/12回答）。雨以外は課金の方向でポリシー強化へ
A24: 予約実績のある店舗 | B24: 20/52店舗 | C24: 32店舗は開設以来予約ゼロ（→需給分析シート）
A25: 取り分/件（5月実測） | B25: 1532 | C25: 完了21件の平均。平均予約単価 ≈ ¥10,200
A27: ■ データ異常（DB再構築・バグ修正への入力）
A28: ・予約番号の重複: 1000000×3件・1000001×3件（採番ロジックのバグ疑い）
A29: ・合計金額¥12,001が3件（¥12,000+1円。金額計算バグ疑い）
A30: ・完全な空行が2件
A31: ・延長料金に手数料が掛かっていない（延長3件・計¥23,650 → 約¥3,500の取りこぼし）

Sheet 収益の論点
A1: 収益の論点（優先度順）
A2: 分析日: 2026-06-11（本番データ）。出典・検証経緯は「出典と経緯」シート参照
A4: ■ 論点① 店頭決済の手数料は「紙請求で回収済み」と判明（6/12定例）— 論点は未回収から『見える化』へ
A5: 支払い方法 | B5: 件数 | C5: 手数料計 | D5: 請求済みフラグ
A6: クレジットカード決済 | B6: 6 | C6: 10780 | D6: はい（Pay.jpが自動分配）
A7: 店頭決済 | B7: 43 | C7: 76150 | D7: すべて「いいえ」
A9: ・月次請求用の「手数料月ごと」テーブルは未使用（レコードなし）と確認済み
A10: ・Pay.jp本番: 売上一覧は全期間で10件のみ・入金残高¥8,690 → クレカ経由の実収入は約9千円（店頭決済分は紙請求で別途回収済み）
A11: ・構造問題: カード手数料3.3%は店舗負担のため、店舗には店頭決済に誘導する動機がある（88%が店頭決済）
A13: ■ 打ち手の候補
A14: 案 | B14: 内容 | C14: 評価 | D14: 備考
A15: 1 | B15: 現場キャッシュレス・クレジット1本化（増永さんの既定方針・6/12） | C15: 最も確実 | D15: 延長・店頭オプション追加・当日予約もカード完結にする設計が前提。実現すれば紙請求は廃止でき、ブラックボックスも消える
A16: 2 | B16: 全額集約→手数料控除して振込+店舗月額課金 | C16: 器はある | D16: 増永さんの構想（6/12）:「請求される」より「振り込まれる」方が店舗のやってる感が出て離脱防止になる。月額課金とセットで設計中
A17: 3 | B17: 紙請求額とDB記録の突合 → 不要と判断（6/12） | C17: 中止 | D17: 請求は紙で適切に回っており（15%で請求していたと思われる）検証の必要なしと判断。見える化は案1（カード1本化）で実現する
A19: ■ その他の論点
A20: 論点 | B20: 状態 | C20: 内容
A21: ② 手数料15% | B21: 検証完了 | C21: 2026-05以降の全完了予約で15%を確認。問題なし
A22: ③ 延長料金に手数料なし | B22: 要修正 | C22: 延長分の15%（約¥3,500相当）が取れていない。DB再構築の決済ロジックで対応
A23: ④ キャンセル率23% | B23: 回答済み(6/12) | C23: 天候+日程変更が大半。雨以外は課金の方向でポリシー強化+50円オーソリを設計（タスク#28）

Sheet コスト棚卸し
A1: RINCLE 月次コスト構造の棚卸し
A2: 黄色セル＝実数を記入。「月次固定費 合計」（運営損益ベース）が試算モデルの固定費(B9)とKPI計画の損益分岐ラインに自動連動。開発委託費は投資扱いで別枠（委託費込み合計は参考行）
A4: 項目 | B4: 分類 | C4: 月額 | D4: 状態 | E4: メモ
A5: Bubble Growthプラン（年契約） | B5: 固定 | C5: 18000 | D5: ほぼ確定 | E5: $119/月×約150円。為替と契約明細で要最終確認
A6: 独自ドメイン（rincle.co.jp） | B6: 固定 | C6: 300 | D6: 仮置き | E6: 年額を12分割した概算
A7: Pay.jp 月額固定費 | B7: 固定 | C7: 0 | D7: 確定 | E7: 月額0円・従量のみ。カード手数料3.3%は店舗負担（PAY.JP公表のスタンダード料率（2026年6月時点）。契約上の実料率はPAY.JP管理画面で要確認）
A8: 運営人件費（予約対応・店舗サポート） | B8: 固定 | C8: 0 | D8: 確定(6/12) | E8: 現在は無給で運営（増永さん談・2026-06-12定例）。給与計上を始めたらここを更新
A9: メール配信（SendGrid等Bubble外のツール） | B9: 固定 | C9: 0 | D9: 要確認 | E9: Bubble標準のみなら0円
A10: 会計・請求・その他SaaS | B10: 固定 | C10: 0 | D10: 要確認 | E10: 請求オペを始める場合はここに追加
A11: 開発・保守委託費 | B11: 固定 | C11: 1000000 | D11: 概算 | E11: 準委任契約（瀬野・山本）・月稼働約100万円。事業の運営損益では投資扱いで合計から除外し、下の「委託費込み」で全体の持ち出しを見る
A12: 広告費 | B12: 変動 | C12: 0 | D12: 確定(現状) | E12: 現在ゼロ。スモークテスト開始時に記入
A13: 月次固定費 合計（運営損益ベース・開発委託費を除く） | C13: =SUM(C5:C10)+C12
A14: （参考）開発委託費込みの月次支出 合計 | C14: =SUM(C5:C12)

Sheet 試算モデル
A1: RINCLE ユニットエコノミクス試算モデル
A2: 黄色セル＝前提（自由に変更可） / 青セル＝自動計算。根拠は「出典と経緯」シート参照
A4: ■ 前提（入力）
A5: 手数料率 | B5: 0.15 | C5: 契約15%・2026-05から実装も15%（全件照合済み）。4月以前は10%
A6: 平均予約単価（GMV） | B6: 10200 | C6: 実測: 5月の完了21件平均手数料¥1,532÷15%。6月は大口化で上昇傾向（参考¥25,700）
A7: 月間予約件数 | B7: 21 | C7: 実績: 2026年5月の完了予約（実予約28件、うちキャンセル5・来客待ち等）
A8: 手数料の徴収率 | B8: 1 | C8: 通常は1（店頭決済分も紙請求で回収済み・6/12確認）。Pay.jp入金のみで見る場合は0.12
A9: 月間固定費 | B9: =コスト棚卸し!C13 | C9: 「コスト棚卸し」シートの運営損益ベース合計に自動連動（開発委託費は含まない。含めて見たい場合は実数を直接入力）
A11: ■ 計算結果
A12: RINCLEの取り分 / 件 | B12: =B6*B5
A13: 月間GMV | B13: =B6*B7
A14: 月間収益（徴収率込み） | B14: =B6*B5*B7*B8
A15: 月間損益 | B15: =B14-B9
A16: 損益分岐に必要な予約数 / 月 | B16: =B9/(B6*B5*B8)
A17: 現状件数との倍率 | B17: =B16/B7
A20: ■ 月間損益マトリクス（行=月間予約件数、列=月間固定費）※手数料率・単価・徴収率は上の前提に連動
A21: 件数＼固定費 | B21: 20000 | C21: 100000 | D21: 300000 | E21: 500000
A22: 10 | B22: =$A22*$B$6*$B$5*$B$8-B$21 | C22: =$A22*$B$6*$B$5*$B$8-C$21 | D22: =$A22*$B$6*$B$5*$B$8-D$21 | E22: =$A22*$B$6*$B$5*$B$8-E$21
A23: 20 | B23: =$A23*$B$6*$B$5*$B$8-B$21 | C23: =$A23*$B$6*$B$5*$B$8-C$21 | D23: =$A23*$B$6*$B$5*$B$8-D$21 | E23: =$A23*$B$6*$B$5*$B$8-E$21
A24: 41 | B24: =$A24*$B$6*$B$5*$B$8-B$21 | C24: =$A24*$B$6*$B$5*$B$8-C$21 | D24: =$A24*$B$6*$B$5*$B$8-D$21 | E24: =$A24*$B$6*$B$5*$B$8-E$21
A25: 60 | B25: =$A25*$B$6*$B$5*$B$8-B$21 | C25: =$A25*$B$6*$B$5*$B$8-C$21 | D25: =$A25*$B$6*$B$5*$B$8-D$21 | E25: =$A25*$B$6*$B$5*$B$8-E$21
A26: 80 | B26: =$A26*$B$6*$B$5*$B$8-B$21 | C26: =$A26*$B$6*$B$5*$B$8-C$21 | D26: =$A26*$B$6*$B$5*$B$8-D$21 | E26: =$A26*$B$6*$B$5*$B$8-E$21
A27: 113 | B27: =$A27*$B$6*$B$5*$B$8-B$21 | C27: =$A27*$B$6*$B$5*$B$8-C$21 | D27: =$A27*$B$6*$B$5*$B$8-D$21 | E27: =$A27*$B$6*$B$5*$B$8-E$21
A28: 150 | B28: =$A28*$B$6*$B$5*$B$8-B$21 | C28: =$A28*$B$6*$B$5*$B$8-C$21 | D28: =$A28*$B$6*$B$5*$B$8-D$21 | E28: =$A28*$B$6*$B$5*$B$8-E$21
A29: 200 | B29: =$A29*$B$6*$B$5*$B$8-B$21 | C29: =$A29*$B$6*$B$5*$B$8-C$21 | D29: =$A29*$B$6*$B$5*$B$8-D$21 | E29: =$A29*$B$6*$B$5*$B$8-E$21
A31: ⚠ 店頭決済43件の手数料¥76,150はDB上「請求済み=いいえ」だが、実態は紙請求で回収済み（15%で請求していたと思われる・6/12）。突合は不要と判断済み

Sheet 月別実績
A1: 月別の実予約実績（source/reserve.csv・予約番号あり・返却日ベース、2026-06-11時点）
A2: 月 | B2: 完了予約 | C2: 手数料収入(実額) | D2: 推定GMV | E2: メモ
A3: 2025-10 | B3: 1 | C3: 3465 | D3: =IF(B3=0,0,C3/IF(A3<"2026-05",0.1,0.15)) | E3: 実予約4・キャンセル3
A4: 2025-11 | B4: 4 | C4: 12980 | D4: =IF(B4=0,0,C4/IF(A4<"2026-05",0.1,0.15))
A5: 2025-12 | B5: 0 | C5: 0 | D5: =IF(B5=0,0,C5/IF(A5<"2026-05",0.1,0.15))
A6: 2026-01 | B6: 0 | C6: 0 | D6: =IF(B6=0,0,C6/IF(A6<"2026-05",0.1,0.15))
A7: 2026-02 | B7: 5 | C7: 4345 | D7: =IF(B7=0,0,C7/IF(A7<"2026-05",0.1,0.15))
A8: 2026-03 | B8: 5 | C8: 4730 | D8: =IF(B8=0,0,C8/IF(A8<"2026-05",0.1,0.15)) | E8: キャンセル1
A9: 2026-04 | B9: 9 | C9: 13823 | D9: =IF(B9=0,0,C9/IF(A9<"2026-05",0.1,0.15)) | E9: 実予約15・キャンセル6・ここまで手数料10%
A10: 2026-05 | B10: 21 | C10: 32175 | D10: =IF(B10=0,0,C10/IF(A10<"2026-05",0.1,0.15)) | E10: 実予約28・キャンセル5・15%適用開始
A11: 2026-06 | B11: 4 | C11: 15412 | D11: =IF(B11=0,0,C11/IF(A11<"2026-05",0.1,0.15)) | E11: 6/11時点・大口傾向
A12: 累計 | B12: =SUM(B3:B11) | C12: =SUM(C3:C11) | D12: =SUM(D3:D11)
A15: 実態: 完了49件(手数料記録100%) / キャンセル16件(23%) / 店頭決済43件¥76,150はDB上未請求表示だが紙請求で回収済み(6/12) / 予約実績は20/52店舗のみ

Sheet KPIツリー
A1: KPIツリー — 収益の分解地図
A2: 数字は2026年5月の実測。〔KGI〕〔KPI n〕は「KPI計画/進捗」シートで毎月追跡する指標
A3: ★運用ルール: 施策を始める前に「この施策はツリーのどのノードを動かすためのものか」を必ず1つ指定する。指定できない施策は思いつきの可能性が高いので保留
A5: 月間手数料収益〔KGI〕 | B5: 実入金¥1,320（Pay.jp分のみ）/ 記録上¥32,175 | C5: 参考: KPI計画シートに試算あり（目標としては凍結中・2026-06-12方針）
A6: ├─ GMV（流通総額）〔参考指標〕 | B6: 約¥215,000/月
A7: │ ├─ 完了予約数〔KPI1〕 | B7: 21件/月
A8: │ │ ├─ 実予約数 | B8: 28件/月
A9: │ │ │ ├─ セッション数〔KPI3〕 ★ボトルネック2 | B9: 約700ユニークIP/月 | C9: 12月に必要なのは約2,600/月（3.7倍）
A10: │ │ │ │ ├─ Organic Search〔KPI4〕 | B10: ほぼゼロ | C10: GA4設置後に計測開始。現状インデックス2〜3頁
A11: │ │ │ │ ├─ Direct / Referral（ショップ経由） | B11: 内訳未計測
A12: │ │ │ │ ├─ Social | B12: 未運用
A13: │ │ │ │ └─ Paid | B13: ¥0・未出稿
A14: │ │ │ └─ 予約CVR〔KPI5〕 | B14: 約4% | C14: 健全水準。分母=流入が先
A15: │ │ └─ キャンセル率〔参考指標〕 | B15: 23% | C15: 天候+日程変更が大半（6/12回答）
A16: │ └─ 平均予約単価 | B16: 約¥10,200 | C16: 6月は大口化で上昇傾向
A17: ├─ 手数料率 | B17: 15%（2026-05〜・検証済み） | C17: 店舗負担計18.3%＝上限。これ以上触らない
A18: └─ 回収率〔KPI2〕 ★ボトルネック1 | B18: 5月4% / 累計12% | C18: 6/12判明: 紙請求で回収済み（15%請求と思われる・突合は不要と判断）。見える化はカード1本化の実現で担保する
A19: ├─ クレカ決済比率 | B19: 完了49件中6件=12% | C19: Pay.jpが自動回収
A20: └─ 店頭決済の請求オペ | B20: 紙請求で稼働中（システム外） | C20: DB上は未請求表示だが、実際は紙請求で回収済み（6/12・突合は不要と判断）
A22: 【供給側の健康指標・ツリーの土台】
A23: 稼働店舗数〔KPI6〕 | B23: 5月: 12/54店 | C23: 当月予約1件以上の店舗数。減少はAnyca型供給崩壊の早期警報（在庫表示率66%とセット監視）
A25: 【将来の第2柱・未稼働】
A26: 物販送客収益 = 完了予約 × 購入相談率 × 成約率 × 送客フィー | B26: ¥0 | C26: 送客フィー¥9,000〜15,000/台 = レンタル6〜10件分
A28: ■ ノード別: 計測手段と対応する施策
A29: ノード | B29: 現在値（2026-05） | C29: 計測手段 / 動かす施策
A30: 回収率 ★1 / KSF1 | B30: 4%（Pay.jp分のみ） | C30: （Pay.jp入金+銀行振込）vs DB手数料 ／ 現場キャッシュレス・クレジット1本化（紙請求の突合は不要と判断・6/12）
A31: セッション数 ★2 / KSF2 | B31: 約700IP/月 | C31: GA4「ユーザー数」（Phase 1・自動） ／ SEO Phase 1 → SEO LP → GBP → OTA → 広告スモークテスト
A32: 流入チャネル内訳 | B32: 未計測 | C32: GA4 参照元/メディア ／ GA4設置が前提。PR TIMES配信の流入効果の計測にも使う（2月スパイクの正体=初配信と6/12判明）
A33: 予約CVR / KSF4 | B33: 約4% | C33: GA4「予約完了」CV÷セッション ／ Tier 1 UI群（検索バー・空き表示・料金明示・キャンセルポリシー）。回収率と流入が先
A34: 予約フロー離脱点 | B34: 未計測 | C34: GA4「予約フローStep別」（Phase 2） ／ フォーム8項目以下・ゲスト予約
A35: キャンセル率 | B35: 23% | C35: DB予約ステータス ／ 雨は無料・それ以外は課金+50円オーソリの設計へ（6/12方針一致）
A36: 平均予約単価 | B36: 約¥10,200 | C36: DB（手数料÷15%） ／ 複数日・複数台レコメンド、E-Bike（在庫79台）の露出強化
A37: 手数料率 | B37: 15% | C37: DB・Pay.jp照合済み ／ 触らない（店舗負担が既に上限）
A38: 購入相談率 | B38: 未計測 | C38: GA4「購入相談クリック」（Phase 3） ／ 試乗履歴つき購入相談予約（T3-5）
A39: 稼働店舗数 / KSF3 | B39: 12/54店 | C39: DB予約の店舗ユニーク数/月 ／ 月次送客レポートメール先行実装・予約ゼロ店舗ヒアリング
A40: 店舗の在庫表示率 | B40: 66%（非表示125/369台） | C40: DB貸出ステータス ／ ヒアリングで非表示理由を確認→表示化サポート。供給側の即効打
A42: ■ 読み方: 今どこから手をつけるか
A43: 1. 入金の見える化（★1/KSF1）が最優先 — 回収自体は紙請求でできている（15%請求と思われる・6/12確認、突合は不要と判断）。カード1本化が実現すれば入金は全てシステム内で捕捉される
A44: 2. セッション数（★2/KSF2）が次 — CVR4%は健全なので流入を増やせば予約はほぼ比例。SEO Phase 1（無料・半日）から着火
A45: 3. CVR改善（UI群/KSF4）はGA4で離脱点が見えてから — 勘で作らない
...

Sheet KPI計画
A1: KPI計画（参考・凍結中 — 2026-06-12方針: 目標設定はユーザー増・差別化実装・UI/UX改善後に再開）
A2: 黄色=前提 / 青=自動計算。このシートの試算は残してあるが、目標としての合意・運用はしていない。再開時に前提を実績で引き直して使う
A4: ■ 前提
A5: 月次成長率（完了予約） | B5: 0.2 | C5: 実績は2ヶ月で倍（≒月+41%）。保守的に+20%で設定
A6: 完了÷実予約（キャンセル等を引いた率） | B6: 0.75 | C6: 実績: 5月 21/28 = 75%
A7: 予約CVR（実予約÷セッション） | B7: 0.04 | C7: 実績: 5月 約4%
A8: 取り分/件 | B8: 1530 | C8: 実績: 4〜5月の手数料平均
A9: 6月の完了予約 見込み | B9: 26 | C9: 6/11時点で4件完了+来客待ち。5月21件×1.2で仮置き
A10: 人件費の想定額（中間目標の判定用） | B10: 60000 | C10: 当初仮置きしていた月6万円を中間目標のラインに再利用。実際に給与計上を始めたら「コスト棚卸し」に記入し、ここはその金額に合わせる
A12: ■ 月次計画（7月〜12月）
A13: 指標 | B13: 2026-07 | C13: 2026-08 | D13: 2026-09 | E13: 2026-10 | F13: 2026-11 | G13: 2026-12
A14: 完了予約数〔KPI1〕 | B14: =ROUND($B$9*(1+$B$5),0) | C14: =ROUND(B14*(1+$B$5),0) | D14: =ROUND(C14*(1+$B$5),0) | E14: =ROUND(D14*(1+$B$5),0) | F14: =ROUND(E14*(1+$B$5),0) | G14: =ROUND(F14*(1+$B$5),0)
A15: 実予約数（完了÷75%） | B15: =B14/$B$6 | C15: =C14/$B$6 | D15: =D14/$B$6 | E15: =E14/$B$6 | F15: =F14/$B$6 | G15: =G14/$B$6
A16: 必要セッション数〔KPI3〕 | B16: =ROUND(B15/$B$7,0) | C16: =ROUND(C15/$B$7,0) | D16: =ROUND(D15/$B$7,0) | E16: =ROUND(E15/$B$7,0) | F16: =ROUND(F15/$B$7,0) | G16: =ROUND(G15/$B$7,0)
A17: うちOrganic Search（目安・手置き）〔KPI4〕 | B17: 30 | C17: 60 | D17: 120 | E17: 250 | F17: 400 | G17: 600
A18: 回収率〔KPI2〕 | B18: 0.5 | C18: 1 | D18: 1 | E18: 1 | F18: 1 | G18: 1 | H18: この行は「入金をPay.jp+銀行振込で捕捉できる率」（6/12更新・詳細は下の✅注記）
A19: 【KGI】月間実入金 | B19: =B14*$B$8*B18 | C19: =C14*$B$8*C18 | D19: =D14*$B$8*D18 | E19: =E14*$B$8*E18 | F19: =F14*$B$8*F18 | G19: =G14*$B$8*G18
A20: （参考）GMV | B20: =B14*$B$8/0.15 | C20: =C14*$B$8/0.15 | D20: =D14*$B$8/0.15 | E20: =E14*$B$8/0.15 | F20: =F14*$B$8/0.15 | G20: =G14*$B$8/0.15
A21: 稼働店舗数〔KPI6〕 | B21: 14 | C21: 16 | D21: 18 | E21: 20 | F21: 22 | G21: 25
A23: 損益分岐ライン（コスト棚卸しの固定費合計） | B23: =コスト棚卸し!$C$13 | C23: =コスト棚卸し!$C$13 | D23: =コスト棚卸し!$C$13 | E23: =コスト棚卸し!$C$13 | F23: =コスト棚卸し!$C$13 | G23: =コスト棚卸し!$C$13
A24: 判定（実入金≧現状固定費？）※無給前提の固定費¥18,300なので7月からクリアする形式的なライン | B24: =IF(B19>=B23,"クリア","") | C24: =IF(C19>=C23,"クリア","") | D24: =IF(D19>=D23,"クリア","") | E24: =IF(E19>=E23,"クリア","") | F24: =IF(F19>=F23,"クリア","") | G24: =IF(G19>=G23,"クリア","")
A25: 判定（人件費を計上しても黒字？）= 中間目標。実入金 ≧ 固定費+人件費想定 | B25: =IF(B19>=B23+$B$10,"クリア","") | C25: =IF(C19>=C23+$B$10,"クリア","") | D25: =IF(D19>=D23+$B$10,"クリア","") | E25: =IF(E19>=E23+$B$10,"クリア","") | F25: =IF(F19>=F23+$B$10,"クリア","") | G25: =IF(G19>=G23+$B$10,"クリア","")
A26: ■ KGI案の言葉での要約
A27: 「2026年12月に月間実入金¥120,000（中間マイルストーン: 10月に人件費を計上しても黒字 = 実入金が固定費+人件費想定6万円の約¥78,000を超える）」。前提は保守的成長+20%/月と8月からの捕捉率100%（紙請求分含む）。6/12に固定費がほぼゼロ（無給）と判明したため、素の損益分岐は7月にクリアしてしまい中間目標にならない → 人件費込みラインを中間目標とする。クライアントと協議の上、成長率・捕捉開始月・人件費想定のセル（黄色）を直して確定させる。確定後はこの数字がKPI進捗シートの目標に自動で入る。なお開発委託費（準委任・月稼働約100万円）は投資として別枠管理 — これを含めた全体の持ち出しはコスト棚卸しシートの参考行を参照
A29: ⚠ クライアントと目標を確定したら: KPI進捗シートの目標列（計画へのリンク）をコピー→「値として貼り付け」で固定すること。固定後はこのシートをいじっても過去の目標は動かなくなる（このシートは来期計画の検討用として残す）
A31: ✅ 確認#1は回答済み（6/12）: 店頭決済分は紙請求で回収できている（15%で請求していたと思われる・突合は不要と判断）→ KGIの「実入金」定義は「Pay.jp入金+銀行振込（紙請求）」。回収率の行は「請求・入金の捕捉率」として運用（カードオンリー化が実現すれば自動的に100%）。※目標設定自体は凍結中

Sheet KPI進捗
A1: KPI進捗管理
A2: 月1回、実績列だけ更新（DBエクスポート+Pay.jp、所要15分）。目標・達成率の運用は凍結中（2026-06-12方針）— 再開時にKPI計画から目標を反映する
E3: ※6月は6/11時点
A4: 指標 | B4: 毎月どこから取るか | C4: 2026-05 実績 | D4: 2026-06 実績 | E4: 2026-07 | H4: 2026-08
E5: 目標 | F5: 実績 | G5: 達成率 | H5: 目標 | I5: 実績 | J5: 達成率
A6: 【KGI】月間手数料収益（実入金） | B6: Pay.jp入金一覧の当月内訳 + 銀行振込（紙請求）の入金額（6/12更新） | C6: 1320 | D6: — | F6: =KPI計画!B19 | G6: =IF(OR(E6="",F6=""),"",F6/E6) | H6: =KPI計画!C19 | J6: =IF(OR(H6="",I6=""),"",I6/H6)
A7: KPI1 完了予約数 | B7: reserve.csv（ステータス=返却済み） | C7: 21 | D7: 4 | F7: =KPI計画!B14 | G7: =IF(OR(E7="",F7=""),"",F7/E7) | H7: =KPI計画!C14 | J7: =IF(OR(H7="",I7=""),"",I7/H7)
A8: KPI2 回収率（実入金÷手数料記録） | B8: （Pay.jp入金+銀行振込）÷ reserve.csvの手数料合計（6/12更新: 紙請求分を含める） | C8: 0.041025259 | D8: — | F8: =KPI計画!B18 | G8: =IF(OR(E8="",F8=""),"",F8/E8) | H8: =KPI計画!C18 | J8: =IF(OR(H8="",I8=""),"",I8/H8)
A9: KPI3 月間セッション | B9: access-logs.csvのユニークIP → GA4設置後は「ユーザー数」 | C9: 702 | D9: — | F9: =KPI計画!B16 | G9: =IF(OR(E9="",F9=""),"",F9/E9) | H9: =KPI計画!C16 | J9: =IF(OR(H9="",I9=""),"",I9/H9)
A10: KPI4 Organic Search流入 | B10: GA4 集客レポート（Phase 1設置後に計測開始） | C10: — | D10: — | F10: =KPI計画!B17 | G10: =IF(OR(E10="",F10=""),"",F10/E10) | H10: =KPI計画!C17 | J10: =IF(OR(H10="",I10=""),"",I10/H10)
A11: KPI5 予約CVR（実予約÷セッション） | B11: reserve.csv実予約 ÷ KPI3 | C11: 0.03988604 | D11: — | F11: 0.04 | G11: =IF(OR(E11="",F11=""),"",F11/E11) | H11: 0.04 | J11: =IF(OR(H11="",I11=""),"",I11/H11)
A12: KPI6 稼働店舗数（当月予約あり） | B12: reserve.csvの店舗ユニーク数 | C12: 12 | D12: 5 | F12: =KPI計画!B21 | G12: =IF(OR(E12="",F12=""),"",F12/E12) | H12: =KPI計画!C21 | J12: =IF(OR(H12="",I12=""),"",I12/H12)
A13: （参考）GMV | B13: reserve.csv手数料合計 ÷ 15% | C13: 214502 | D13: 102750 | F13: =KPI計画!B20 | G13: =IF(OR(E13="",F13=""),"",F13/E13) | H13: =KPI計画!C20 | J13: =IF(OR(H13="",I13=""),"",I13/H13)
A14: （参考）キャンセル率 | B14: reserve.csv（キャンセル÷実予約） | C14: 0.17857143 | D14: — | G14: =IF(OR(E14="",F14=""),"",F14/E14) | J14: =IF(OR(H14="",I14=""),"",I14/H14)
A15: （参考）新規利用者登録 | B15: users.csv（当月のCreation Date） | C15: 26 | D15: — | G15: =IF(OR(E15="",F15=""),"",F15/E15) | J15: =IF(OR(H15="",I15=""),"",I15/H15)
A17: 9月以降の列は8月の3列（目標/実績/達成率）をコピーして右に足す。KPI4はGA4設置後に「—」を実数に置き換える
A19: ■ なぜKGIが「月間手数料収益（実入金）」なのか
A20: 採用: 実入金 | B20: 実入金 = GMV × 手数料率15% × 回収率 の最終結果。今のRINCLEの2大ボトルネック（入金の捕捉率・流入700IP/月）の両方を改善しないと動かない数字なので、これを最終目標に置くと努力の漏れがなくなる
A21: 不採用: 完了予約数 | B21: 予約が増えても入金を捕捉できなければ手元の数字は増えない。実際Pay.jpだけ見ると8ヶ月で¥8,690に見え、紙請求の実態が把握できていなかった。KPI1として並走
A22: 不採用: GMV（流通総額） | B22: マーケットプレイスの定番指標だが「お客さんが払ったお金の合計」であって「RINCLEに入ったお金」ではない。回収問題がある今はKGIに不適。参考指標として並走
A23: 将来の見直し条件 | B23: 回収問題が解決して回収率が安定的に100%になったら、実入金はGMV×15%と同じ意味になる。その時点でKGIをGMVに切り替えてよい（プラットフォームの成長そのものを追う段階に移行）
A24: 決定日: 2026-06-11（候補3案の比較から選定）
A26: ■ KGI → KSF → KPI の対応（なぜこの6個を測るのか）
A27: KSF（成功のカギ・言葉） | B27: なぜカギなのか | C27: 測るKPI
A28: KSF1: 手数料を確実に回収する仕組みを作る | B28: 売上の88%（店頭決済分）が紙請求のシステム外回収でブラックボックス（6/12判明・回収自体はできている）。決済のシステム内化（カード1本化）で実入金の自動把握・自動回収を実現する | C28: KPI2 回収率
A29: KSF2: サイトに人を連れてくる（SEO・店舗経由・OTA） | B29: CVR4%は健全なので、流入さえ増えれば予約はほぼ比例して増える構造。12月に必要なセッションは現在の3.7倍（2,567） | C29: KPI3 セッション / KPI4 Organic流入
A30: KSF3: 店舗網を死なせない（待っている52店の維持・活性化） | B30: 42店は当月予約ゼロが常態。離脱が始まると供給網ごと崩壊する（Anycaの教訓）。月次送客レポートと非表示在庫の解消で「待つ価値」を見せ続ける | C30: KPI6 稼働店舗数
A31: KSF4: 予約体験の質を落とさない | B31: 成長の前提条件。CVRが下がると流入を増やしても無駄になる（攻めではなく守りのKSF） | C31: KPI5 予約CVR / KPI1 完了予約数
A32: ※ KPI1（完了予約数）はKSF2〜4すべての結果として動く「結果指標」。KSFの詳しい分解は「KPIツリー」シートを参照

Sheet 需給分析
A1: 需給バランス（2026-06-11 全テーブル解析）
A2: 分析日: 2026-06-11（本番データ）。出典・検証経緯は「出典と経緯」シート参照
A4: ■ 供給側: 思ったより整っている
A5: 指標 | B5: 値 | C5: 備考
A6: 自転車登録 | B6: 369台 | C6: ロード167 / ミニベロ103 / クロス74 / MTB20 / キッズ5。E-Bike 79台
A7: 自転車を登録済みの店舗 | B7: 50/54店 | C7: ゼロは4店のみ（うち3店は店名に「準備中」明記）
A8: Pay.jp審査通過（カード決済可） | B8: 54/54店（全店）
A9: 「ユーザー非表示」の自転車 | B9: 125台（34%） | C9: 予約ゼロ店舗では在庫の52%が非表示。理由はヒアリングで確認
A11: ■ 需要側: 明確にここがボトルネック
A12: 指標 | B12: 値 | C12: 備考
A13: 利用者登録 | B13: 91人 | C13: 2月15 → 3月16 → 4月18 → 5月26人と加速中
A14: サイトアクセス | B14: 月2,300PV / 約700IP（2026-05） | C14: 2026-02のスパイク（3,402PV/1,603IP）はPR TIMES初配信と判明（6/12）。再現可能な集客施策
A15: 粗いCVR | B15: 約4%（700IP→実予約28件） | C15: 悪くない水準。問題は分子より分母=流入量
A17: ■ 地理ミスマッチ: 予約は関西に偏在、在庫は全国に滞留
A18: ・予約上位5店はすべて関西圏（神戸17 / 尼崎12 / 京都7 / 箕面5 / 奈良5）。上位2店で全予約の41%
A19: ・予約ゼロで在庫最多: LORO横浜31台 / LORO尾道22台 / SPZ熊本18台
A20: ・しまなみ海道の玄関口・尾道で22台が予約ゼロ → 集客施策の地域優先順位を決める一次データ
A21: ・store_00XX@pedalstandard.com名義の店舗（運営社ドメイン）が4件 → 正体要確認

Sheet 確認リスト
A1: クライアント確認リスト（回答欄つき）
A2: 分析日: 2026-06-11（本番データ）。出典・検証経緯は「出典と経緯」シート参照
A4: # | B4: 確認事項 | C4: 分かると何が決まるか | D4: 回答（記入欄）
A5: 1 | B5: 店頭決済の手数料、システム外（銀行振込等）で回収した実績はあるか | C5: 実収入が¥8,690で全部かの最終確定。過去分¥76,150の扱いと回収方式の意思決定 | D5: 【回答あり・6/12】回収できている。15%を紙の請求書でシステム外請求（簡易運用・紙でも15%で請求していたと思われる）。突合は不要と判断（6/12）。今後は「運営が全額集約→手数料を引いて振込」+現場キャッシュレス（クレジット1本化）+店舗月額課金の方向で検討中
A6: 2 | B6: キャンセル16件の理由内訳 | C6: キャンセルポリシー施策のコスト試算 | D6: 【回答あり・6/12】天候 + 日程変更（キャンセル→別日再予約）が大半、一部不明。キャンセルポリシーは「弱い・強めにする必要」で増永さんも認識一致。雨以外は課金する方向で設計検討へ（50円オーソリでカード有効性チェック案が有力）
A7: 3 | B7: 運営の月額固定費（人件費・ツール） | C7: 損益分岐ラインの確定（→コスト棚卸しシートに記入） | D7: 【回答あり・6/12】ほぼかかっていない。運営は現在無給、システム系の費用（Bubble等）+開発委託のみ → コスト棚卸しに反映済み
A8: 4 | B8: 2026年2月のアクセス急増（3,402PV/1,603IP）の要因 | C8: 再現可能な集客施策かボットかの判別 | D8: 【回答あり・6/12】PR TIMES初配信だった（世の中に初めて出したタイミング、メディア掲載が連鎖）。再現可能 → 来週「50店舗突破」リリース配信予定、100店舗で専門誌+広告も計画
A9: 5 | B9: リピート率（要: 乗車人情報テーブルのエクスポート） | C9: リピート率・アクティベーション率の初計測 | D9: （6/12は時間切れで未依頼 → 来週のデータ認識合わせで依頼する）
A10: 6 | B10: 「100店舗」の出所 | C10: 店舗数・予約数の実態補正 | D10: 【回答あり・6/12】「100店舗」=営業ベースの見込み（実働50店+契約進行中+20店、営業済み120〜130店。数ヶ月で100到達見込み）。store_00XX名義は未確認のまま
A11: 7 | B11: 対外的な店舗数の表記をどうするか（公式サイト/プレスは24店舗、DBは54店登録・うち準備中4店） | C11: 競合分析・プレゼンHTML等の「24店舗/12都府県」表記を一括更新できる。現状は資料間で数字が不一致のまま Meta情報にも関連 | D11: 【協議中・6/12】来週「50店舗以上」のPR TIMES配信予定。表記は「全国100店舗以上」で決め打ちする案を含め1〜2週間で決定。バイク数（約360台、CycleTrip300台超え）も訴求に使う方向
A12: 8 | B12: PAY.JPの契約プランと実際の決済手数料率（公表は3.3%。契約書か管理画面で確認） | C12: 店舗の合計負担率（現在は15%+3.3%=18.3%で記載）が確定する。Stripe載せ替え時のコスト比較の前提にもなる

Sheet 出典と経緯
A1: 出典と検証の経緯
A2: このブックが「収益モデル」の正本（2026-06-12にmdから完全移行）。分析日: 2026-06-11
A4: ■ データソース
A5: 本番DBエクスポート | B5: source/ フォルダ（gitignore対象・コミットされない）: reserve.csv（予約121レコード全列）/ users.csv（146人: ユーザー91・加盟店54・管理者1）/ bicycle.csv（369台）/ shop.csv / access-logs.csv（13,596行）/ bike-option.csv — いずれも2026-06-11取得
A6: Pay.jp本番スクリーンショット | B6: source/payjp/ 売り上げ一覧.png（全期間で10件のみ）・入金一覧.png（残高¥8,690・次回入金¥6,940）— 2026-06-11取得
A7: 決済フローの仕様 | B7: 98_presentations/pay.jp/asis.html（手数料15%・カード手数料3.3%店舗負担・ライド開始時課金・店頭決済の未請求フォールバック）
A9: ■ 検証の経緯（重要な訂正履歴）
A10: 「予約の60%に手数料記録がない」→ 誤分析と判明 | B10: 全列エクスポートで再検証した結果、記録がない行は仮情報51・キャンセル16・来客待ち5で、完了49件の記録は100%。本当の問題は「記録はあるが店頭決済分¥76,150が未請求」（→収益の論点シート）
A11: 「15%修正が効いていない疑い」→ 晴れた | B11: 5月の平均手数料/件が4月と同額だったため疑ったが、合計金額との照合で5月完了21件すべて15%と確認。平均が変わらなかったのは5月の予約単価が小さめだっただけ
A12: 「LCP 3〜5秒」→ 実測49.3秒 | B12: Lighthouse実測（2026-06-11、モバイル・slow 4G）: スコア25/FCP 20.3s/LCP 49.3s/総重量9.2MB。詳細は current-issues-and-solutions.md
A13: 「店舗100」→ DBは54店 | B13: 口頭情報とDBが不一致 → 6/12回答: 「100」は営業ベースの見込み（実働50店+契約進行中20店）
A15: ■ 関連ドキュメント
A16: 「KPIツリー」シート | B16: 収益の分解ツリーと優先順位（ボトルネック=入金の見える化とセッション数）
A17: shop-hearing-design.md | B17: ヒアリング設計（対象店舗は需給分析シートのデータで実名選定済み）
A18: current-issues-and-solutions.md | B18: 課題と対策の全体像（収益モデル・保険・ステマ規制のセクションあり）
A19: ../03_seo/seo-setup-guide.md | B19: SEO Phase 1の実施手順
A21: ■ 主な外部出典
A22: OTA手数料相場 | B22: アソビュー10〜20% / KLOOK 15〜20% / じゃらん16.4%（詳細出典は action-plan.md / current-issues-and-solutions.md に記載）
A23: 物販送客の根拠 | B23: Trek: レンタル料100%を購入代金に充当 https://www.trekbikes.com/us/en_US/trek-bike-rentals/ / レンティオ: レンタル経由で購入数4倍以上 https://www.rentio.co.jp/enterprise/column/renttoown
A24: 供給側崩壊の先行事例 | B24: Anyca（2024年終了・手数料15〜35%で供給離反） https://www.watch.impress.co.jp/docs/news/1631359.html / Spinlister（2018年終了）
A26: ■ 主要数値の出典対応表（この数字どこから？）
A27: 数値 | B27: 値 | C27: 出典・確認方法
A28: 手数料率 | B28: 15% | C28: クライアント確認（2026-05切替）+ reserve.csv で5月完了21件全件「合計金額×15%=手数料」を照合して裏取り
A29: カード手数料3.3%は店舗負担 | B29: — | C29: PAY.JP公表のスタンダード料率 https://pay.jp/plan （2026年6月時点・2026-09-14再確認）。旧値「約3.5%」からの訂正は本シート下部の訂正履歴を参照
A30: 登録店舗数 | B30: 54店 | C30: users.csv の Right=加盟店 を集計（アーカイブ2店含む）
A31: 登録利用者数 | B31: 91人 | C31: users.csv の Right=ユーザー を集計
A32: 実予約70件 / 完了49 / キャンセル16 | B32: — | C32: reserve.csv のステータス列+予約番号の有無で集計（仮情報51件は除外）
A33: 月別の完了予約数・手数料収入 | B33: 月別実績シート | C33: reserve.csv の返却日×手数料デフォルト列を月別集計
A34: RINCLEの実入金 | B34: ¥8,690（Pay.jp=クレカ分のみ） | C34: Pay.jp本番管理画面のスクショ（source/payjp/入金一覧.png）
A35: 店頭決済の手数料（DB上は未請求表示） | B35: ¥76,150 | C35: reserve.csv の支払い方法=店頭決済 43件の手数料合計。DB上は全件「請求済み=いいえ」+ 手数料月ごとテーブル未使用だが、実際は紙請求で回収済み（6/12回答）
A36: 平均予約単価 | B36: 約¥10,200 | C36: 5月実測の手数料平均¥1,532 ÷ 15% で逆算
A37: 自転車369台 / E-Bike79台 / 非表示125台 | B37: — | C37: bicycle.csv（カテゴリ・ebike・貸出ステータス列を集計）
A38: 月間アクセス 約700IP / 2,300PV | B38: 2026-05 | C38: access-logs.csv（13,596行）を月別集計。IP=ユニークIPアドレス数
... A43: 開発委託費 約100万円/月 | B43: 概算 | C43: 準委任契約の月間稼働額（瀬野さんヒアリング・2026-06-12）。運営損益からは投資扱いで除外、コスト棚卸しの参考行で管理
A44: ■ 今後の調査余地（手元データで追加分析できること）
A45: 予約フローの離脱率 | B45: 仮情報51件と実予約70件を自転車予約詳細IDで突合すれば、「予約を始めたが確定しなかった割合」が出せる（CVR改善の優先判断に使える）
A46: リピート率 | B46: 乗車人情報テーブルのエクスポートが届けば計測可能（確認リスト#5）
A47: DBバグの引き継ぎ | B47: 実態サマリーの「データ異常」4件（予約番号重複・¥12,001・空行・延長手数料）は、DB再構築プロジェクトのバグリスト（2_requirements）へ転記すること
A49: ■ 2026-06-12定例での判明事項（議事録: 1_meeting_minutes/6.12.txt）
A50: 店頭決済の回収 | B50: 紙の請求書でシステム外回収できていた（15%で請求していたと思われる・増永さんの運用認識）。「未回収¥76,150」という当初分析はPay.jp/DBだけを見た結論で、実態は回収済み
...
